<?xml version="1.0"?>
<robot name="ur3e">

  <!-- materials -->
  <material name="ur_blue">
    <color rgba="0.0 0.22 0.52 1.0"/>
  </material>
  <material name="ur_silver">
    <color rgba="0.70 0.70 0.70 1.0"/>
  </material>
  <material name="ur_dark">
    <color rgba="0.20 0.20 0.20 1.0"/>
  </material>

  <!-- ==================== base ==================== -->
  <link name="base_link">
    <visual>
      <geometry><cylinder radius="0.038" length="0.050"/></geometry>
      <origin xyz="0 0 0.025" rpy="0 0 0"/>
      <material name="ur_dark"/>
    </visual>
    <collision>
      <geometry><cylinder radius="0.038" length="0.050"/></geometry>
      <origin xyz="0 0 0.025" rpy="0 0 0"/>
    </collision>
    <inertial>
      <mass value="2.0"/>
      <origin xyz="0 0 0.025"/>
      <inertia ixx="1e-3" ixy="0" ixz="0" iyy="1e-3" iyz="0" izz="1e-3"/>
    </inertial>
  </link>

  <!-- ==================== shoulder pan ==================== -->
  <joint name="shoulder_pan_joint" type="revolute">
    <parent link="base_link"/>
    <child  link="shoulder_link"/>
    <origin xyz="0 0 0.15185" rpy="0 0 0"/>
    <axis xyz="0 0 1"/>
    <limit lower="-6.2832" upper="6.2832" effort="56" velocity="3.14"/>
    <dynamics damping="0.5" friction="0.1"/>
  </joint>

  <link name="shoulder_link">
    <visual>
      <geometry><cylinder radius="0.038" length="0.060"/></geometry>
      <origin xyz="0 0 0" rpy="0 0 0"/>
      <material name="ur_blue"/>
    </visual>
    <collision>
      <geometry><cylinder radius="0.038" length="0.060"/></geometry>
      <origin xyz="0 0 0" rpy="0 0 0"/>
    </collision>
    <inertial>
      <mass value="2.0"/>
      <inertia ixx="1e-3" ixy="0" ixz="0" iyy="1e-3" iyz="0" izz="1e-3"/>
    </inertial>
  </link>

  <!-- ==================== shoulder lift ==================== -->
  <joint name="shoulder_lift_joint" type="revolute">
    <parent link="shoulder_link"/>
    <child  link="upper_arm_link"/>
    <origin xyz="0 0 0" rpy="0 1.5707963 0"/>
    <axis xyz="0 1 0"/>
    <limit lower="-6.2832" upper="6.2832" effort="56" velocity="3.14"/>
    <dynamics damping="0.5" friction="0.1"/>
  </joint>

  <link name="upper_arm_link">
    <visual>
      <geometry><box size="0.24355 0.050 0.050"/></geometry>
      <origin xyz="-0.121775 0 0" rpy="0 0 0"/>
      <material name="ur_silver"/>
    </visual>
    <collision>
      <geometry><box size="0.24355 0.050 0.050"/></geometry>
      <origin xyz="-0.121775 0 0" rpy="0 0 0"/>
    </collision>
    <inertial>
      <mass value="1.5"/>
      <origin xyz="-0.121775 0 0"/>
      <inertia ixx="5e-3" ixy="0" ixz="0" iyy="5e-3" iyz="0" izz="1e-3"/>
    </inertial>
  </link>

  <!-- ==================== elbow ==================== -->
  <joint name="elbow_joint" type="revolute">
    <parent link="upper_arm_link"/>
    <child  link="forearm_link"/>
    <origin xyz="-0.24355 0 0" rpy="0 0 0"/>
    <axis xyz="0 1 0"/>
    <limit lower="-6.2832" upper="6.2832" effort="28" velocity="3.14"/>
    <dynamics damping="0.5" friction="0.1"/>
  </joint>

  <link name="forearm_link">
    <visual>
      <geometry><box size="0.2132 0.040 0.040"/></geometry>
      <origin xyz="-0.1066 0 0" rpy="0 0 0"/>
      <material name="ur_blue"/>
    </visual>
    <collision>
      <geometry><box size="0.2132 0.040 0.040"/></geometry>
      <origin xyz="-0.1066 0 0" rpy="0 0 0"/>
    </collision>
    <inertial>
      <mass value="1.0"/>
      <origin xyz="-0.1066 0 0"/>
      <inertia ixx="3e-3" ixy="0" ixz="0" iyy="3e-3" iyz="0" izz="5e-4"/>
    </inertial>
  </link>

  <!-- ==================== wrist 1 ==================== -->
  <joint name="wrist_1_joint" type="revolute">
    <parent link="forearm_link"/>
    <child  link="wrist_1_link"/>
    <origin xyz="-0.2132 0 0.13105" rpy="0 0 0"/>
    <axis xyz="0 1 0"/>
    <limit lower="-6.2832" upper="6.2832" effort="28" velocity="6.28"/>
    <dynamics damping="0.3" friction="0.05"/>
  </joint>

  <link name="wrist_1_link">
    <visual>
      <geometry><cylinder radius="0.025" length="0.050"/></geometry>
      <origin xyz="0 0 0" rpy="1.5707963 0 0"/>
      <material name="ur_silver"/>
    </visual>
    <collision>
      <geometry><cylinder radius="0.025" length="0.050"/></geometry>
      <origin xyz="0 0 0" rpy="1.5707963 0 0"/>
    </collision>
    <inertial>
      <mass value="0.5"/>
      <inertia ixx="3e-4" ixy="0" ixz="0" iyy="3e-4" iyz="0" izz="3e-4"/>
    </inertial>
  </link>

  <!-- ==================== wrist 2 ==================== -->
  <joint name="wrist_2_joint" type="revolute">
    <parent link="wrist_1_link"/>
    <child  link="wrist_2_link"/>
    <origin xyz="0 -0.08535 0" rpy="0 0 0"/>
    <axis xyz="0 0 1"/>
    <limit lower="-6.2832" upper="6.2832" effort="28" velocity="6.28"/>
    <dynamics damping="0.3" friction="0.05"/>
  </joint>

  <link name="wrist_2_link">
    <visual>
      <geometry><cylinder radius="0.025" length="0.050"/></geometry>
      <origin xyz="0 0 0" rpy="0 0 0"/>
      <material name="ur_silver"/>
    </visual>
    <collision>
      <geometry><cylinder radius="0.025" length="0.050"/></geometry>
      <origin xyz="0 0 0" rpy="0 0 0"/>
    </collision>
    <inertial>
      <mass value="0.5"/>
      <inertia ixx="3e-4" ixy="0" ixz="0" iyy="3e-4" iyz="0" izz="3e-4"/>
    </inertial>
  </link>

  <!-- ==================== wrist 3 ==================== -->
  <joint name="wrist_3_joint" type="revolute">
    <parent link="wrist_2_link"/>
    <child  link="wrist_3_link"/>
    <origin xyz="0 0.0921 0" rpy="0 0 0"/>
    <axis xyz="0 1 0"/>
    <limit lower="-6.2832" upper="6.2832" effort="28" velocity="6.28"/>
    <dynamics damping="0.3" friction="0.05"/>
  </joint>

  <link name="wrist_3_link">
    <visual>
      <geometry><cylinder radius="0.020" length="0.040"/></geometry>
      <origin xyz="0 0 0" rpy="1.5707963 0 0"/>
      <material name="ur_dark"/>
    </visual>
    <collision>
      <geometry><cylinder radius="0.020" length="0.040"/></geometry>
      <origin xyz="0 0 0" rpy="1.5707963 0 0"/>
    </collision>
    <inertial>
      <mass value="0.3"/>
      <inertia ixx="1e-4" ixy="0" ixz="0" iyy="1e-4" iyz="0" izz="1e-4"/>
    </inertial>
  </link>

  <!-- ==================== end-effector (fixed) ==================== -->
  <joint name="ee_fixed_joint" type="fixed">
    <parent link="wrist_3_link"/>
    <child  link="ee_link"/>
    <origin xyz="0 0 0" rpy="0 0 1.5707963"/>
  </joint>

  <link name="ee_link">
    <inertial>
      <mass value="0.01"/>
      <inertia ixx="1e-5" ixy="0" ixz="0" iyy="1e-5" iyz="0" izz="1e-5"/>
    </inertial>
  </link>

</robot>
